I'm sorry, but an uncaught exception occurred.

While running game code:
  File "game/scripts/script_burrow1.rpy", line 13, in script
    op "Ah. Back at last, are you?"
Exception: Sayer 'op' is not defined.

-- Full Traceback ------------------------------------------------------------

Full traceback:
  File "game/scripts/script_burrow1.rpy", line 13, in script
    op "Ah. Back at last, are you?"
  File "C:\Users\demim\OneDrive\Documenten\renpy-8.3.6-sdk\renpy\ast.py", line 2586, in execute
    Say.execute(self)
  File "C:\Users\demim\OneDrive\Documenten\renpy-8.3.6-sdk\renpy\ast.py", line 583, in execute
    who = eval_who(self.who, self.who_fast)
  File "C:\Users\demim\OneDrive\Documenten\renpy-8.3.6-sdk\renpy\ast.py", line 472, in eval_who
    raise Exception("Sayer '%s' is not defined." % who)
Exception: Sayer 'op' is not defined.

Windows-10-10.0.22631 AMD64
Ren'Py 8.3.6.25022803
White Tail 1.0
Thu Mar 27 12:12:07 2025
